{
  "test_execution_id": "MCP_TestExecution_20250617_060155",
  "execution_summary": {
    "start_time": "2025-06-17T06:01:49.079250",
    "end_time": "2025-06-17T06:01:55.626988",
    "total_duration": 6.547738,
    "total_tests": 32,
    "passed_tests": 0,
    "failed_tests": 32,
    "timeout_tests": 0,
    "error_tests": 0,
    "success_rate": 0.0
  },
  "module_statistics": {
    "cloud_search_mcp": {
      "total": 2,
      "passed": 0,
      "failed": 2,
      "timeout": 0,
      "error": 0
    },
    "development_intervention_mcp": {
      "total": 2,
      "passed": 0,
      "failed": 2,
      "timeout": 0,
      "error": 0
    },
    "directory_structure_mcp": {
      "total": 2,
      "passed": 0,
      "failed": 2,
      "timeout": 0,
      "error": 0
    },
    "enterprise_smartui_mcp": {
      "total": 2,
      "passed": 0,
      "failed": 2,
      "timeout": 0,
      "error": 0
    },
    "github_mcp": {
      "total": 2,
      "passed": 0,
      "failed": 2,
      "timeout": 0,
      "error": 0
    },
    "interaction_log_manager": {
      "total": 2,
      "passed": 0,
      "failed": 2,
      "timeout": 0,
      "error": 0
    },
    "test_manage_mcp": {
      "total": 2,
      "passed": 0,
      "failed": 2,
      "timeout": 0,
      "error": 0
    },
    "kilocode_mcp": {
      "total": 2,
      "passed": 0,
      "failed": 2,
      "timeout": 0,
      "error": 0
    },
    "local_model_mcp": {
      "total": 2,
      "passed": 0,
      "failed": 2,
      "timeout": 0,
      "error": 0
    },
    "enhanced_workflow_mcp": {
      "total": 2,
      "passed": 0,
      "failed": 2,
      "timeout": 0,
      "error": 0
    },
    "architecture_design_mcp": {
      "total": 2,
      "passed": 0,
      "failed": 2,
      "timeout": 0,
      "error": 0
    },
    "coding_workflow_mcp": {
      "total": 2,
      "passed": 0,
      "failed": 2,
      "timeout": 0,
      "error": 0
    },
    "developer_flow_mcp": {
      "total": 2,
      "passed": 0,
      "failed": 2,
      "timeout": 0,
      "error": 0
    },
    "operations_workflow_mcp": {
      "total": 2,
      "passed": 0,
      "failed": 2,
      "timeout": 0,
      "error": 0
    },
    "release_manager_mcp": {
      "total": 2,
      "passed": 0,
      "failed": 2,
      "timeout": 0,
      "error": 0
    },
    "requirements_analysis_mcp": {
      "total": 2,
      "passed": 0,
      "failed": 2,
      "timeout": 0,
      "error": 0
    }
  },
  "type_statistics": {
    "unit": {
      "total": 16,
      "passed": 0,
      "failed": 16,
      "timeout": 0,
      "error": 0
    },
    "integration": {
      "total": 16,
      "passed": 0,
      "failed": 16,
      "timeout": 0,
      "error": 0
    }
  },
  "detailed_results": [
    {
      "module_name": "cloud_search_mcp",
      "test_type": "unit",
      "test_file": "test_cloud_search_mcp.py",
      "test_path": "mcp/adapter/cloud_search_mcp/unit_tests/test_cloud_search_mcp.py",
      "status": "FAIL",
      "duration": 0.054352,
      "start_time": "2025-06-17T06:01:49.081631",
      "end_time": "2025-06-17T06:01:49.135983",
      "stdout": "",
      "stderr": "Traceback (most recent call last):\n  File \"<frozen runpy>\", line 198, in _run_module_as_main\n  File \"<frozen runpy>\", line 88, in _run_code\n  File \"/usr/lib/python3.11/unittest/__main__.py\", line 18, in <module>\n    main(module=None)\n  File \"/usr/lib/python3.11/unittest/main.py\", line 101, in __init__\n    self.parseArgs(argv)\n  File \"/usr/lib/python3.11/unittest/main.py\", line 150, in parseArgs\n    self.createTests()\n  File \"/usr/lib/python3.11/unittest/main.py\", line 161, in createTests\n    self.test = self.testLoader.loadTestsFromNames(self.testNames,\n                ^^^^^^^^^^^^^^^^^^^^^^^^^^^^^^^^^^^^^^^^^^^^^^^^^^\n  File \"/usr/lib/python3.11/unittest/loader.py\", line 220, in loadTestsFromNames\n    suites = [self.loadTestsFromName(name, module) for name in names]\n             ^^^^^^^^^^^^^^^^^^^^^^^^^^^^^^^^^^^^^^^^^^^^^^^^^^^^^^^^\n  File \"/usr/lib/python3.11/unittest/loader.py\", line 220, in <listcomp>\n    suites = [self.loadTestsFromName(name, module) for name in names]\n              ^^^^^^^^^^^^^^^^^^^^^^^^^^^^^^^^^^^^\n  File \"/usr/lib/python3.11/unittest/loader.py\", line 154, in loadTestsFromName\n    module = __import__(module_name)\n             ^^^^^^^^^^^^^^^^^^^^^^^\n  File \"/opt/powerautomation/mcp/adapter/cloud_search_mcp/__init__.py\", line 5\n    ├── cloud_search_mcp.py          # 核心MCP实现\n    ^\nSyntaxError: invalid character '├' (U+251C)\n",
      "return_code": 1
    },
    {
      "module_name": "cloud_search_mcp",
      "test_type": "integration",
      "test_file": "test_cloud_search_mcp_integration.py",
      "test_path": "mcp/adapter/cloud_search_mcp/integration_tests/test_cloud_search_mcp_integration.py",
      "status": "FAIL",
      "duration": 0.049358,
      "start_time": "2025-06-17T06:01:49.136124",
      "end_time": "2025-06-17T06:01:49.185482",
      "stdout": "",
      "stderr": "Traceback (most recent call last):\n  File \"<frozen runpy>\", line 198, in _run_module_as_main\n  File \"<frozen runpy>\", line 88, in _run_code\n  File \"/usr/lib/python3.11/unittest/__main__.py\", line 18, in <module>\n    main(module=None)\n  File \"/usr/lib/python3.11/unittest/main.py\", line 101, in __init__\n    self.parseArgs(argv)\n  File \"/usr/lib/python3.11/unittest/main.py\", line 150, in parseArgs\n    self.createTests()\n  File \"/usr/lib/python3.11/unittest/main.py\", line 161, in createTests\n    self.test = self.testLoader.loadTestsFromNames(self.testNames,\n                ^^^^^^^^^^^^^^^^^^^^^^^^^^^^^^^^^^^^^^^^^^^^^^^^^^\n  File \"/usr/lib/python3.11/unittest/loader.py\", line 220, in loadTestsFromNames\n    suites = [self.loadTestsFromName(name, module) for name in names]\n             ^^^^^^^^^^^^^^^^^^^^^^^^^^^^^^^^^^^^^^^^^^^^^^^^^^^^^^^^\n  File \"/usr/lib/python3.11/unittest/loader.py\", line 220, in <listcomp>\n    suites = [self.loadTestsFromName(name, module) for name in names]\n              ^^^^^^^^^^^^^^^^^^^^^^^^^^^^^^^^^^^^\n  File \"/usr/lib/python3.11/unittest/loader.py\", line 154, in loadTestsFromName\n    module = __import__(module_name)\n             ^^^^^^^^^^^^^^^^^^^^^^^\n  File \"/opt/powerautomation/mcp/adapter/cloud_search_mcp/__init__.py\", line 5\n    ├── cloud_search_mcp.py          # 核心MCP实现\n    ^\nSyntaxError: invalid character '├' (U+251C)\n",
      "return_code": 1
    },
    {
      "module_name": "development_intervention_mcp",
      "test_type": "unit",
      "test_file": "test_development_intervention_mcp.py",
      "test_path": "mcp/adapter/development_intervention_mcp/unit_tests/test_development_intervention_mcp.py",
      "status": "FAIL",
      "duration": 0.047549,
      "start_time": "2025-06-17T06:01:49.185624",
      "end_time": "2025-06-17T06:01:49.233173",
      "stdout": "",
      "stderr": "Traceback (most recent call last):\n  File \"<frozen runpy>\", line 198, in _run_module_as_main\n  File \"<frozen runpy>\", line 88, in _run_code\n  File \"/usr/lib/python3.11/unittest/__main__.py\", line 18, in <module>\n    main(module=None)\n  File \"/usr/lib/python3.11/unittest/main.py\", line 101, in __init__\n    self.parseArgs(argv)\n  File \"/usr/lib/python3.11/unittest/main.py\", line 150, in parseArgs\n    self.createTests()\n  File \"/usr/lib/python3.11/unittest/main.py\", line 161, in createTests\n    self.test = self.testLoader.loadTestsFromNames(self.testNames,\n                ^^^^^^^^^^^^^^^^^^^^^^^^^^^^^^^^^^^^^^^^^^^^^^^^^^\n  File \"/usr/lib/python3.11/unittest/loader.py\", line 220, in loadTestsFromNames\n    suites = [self.loadTestsFromName(name, module) for name in names]\n             ^^^^^^^^^^^^^^^^^^^^^^^^^^^^^^^^^^^^^^^^^^^^^^^^^^^^^^^^\n  File \"/usr/lib/python3.11/unittest/loader.py\", line 220, in <listcomp>\n    suites = [self.loadTestsFromName(name, module) for name in names]\n              ^^^^^^^^^^^^^^^^^^^^^^^^^^^^^^^^^^^^\n  File \"/usr/lib/python3.11/unittest/loader.py\", line 154, in loadTestsFromName\n    module = __import__(module_name)\n             ^^^^^^^^^^^^^^^^^^^^^^^\n  File \"/opt/powerautomation/mcp/adapter/development_intervention_mcp/unit_tests/__init__.py\", line 1\n    \"\"\"测试模块初始化文件\"\"\"\\n\n                                      ^\nSyntaxError: unexpected character after line continuation character\n",
      "return_code": 1
    },
    {
      "module_name": "development_intervention_mcp",
      "test_type": "integration",
      "test_file": "test_development_intervention_mcp_integration.py",
      "test_path": "mcp/adapter/development_intervention_mcp/integration_tests/test_development_intervention_mcp_integration.py",
      "status": "FAIL",
      "duration": 0.050751,
      "start_time": "2025-06-17T06:01:49.233313",
      "end_time": "2025-06-17T06:01:49.284064",
      "stdout": "",
      "stderr": "Traceback (most recent call last):\n  File \"<frozen runpy>\", line 198, in _run_module_as_main\n  File \"<frozen runpy>\", line 88, in _run_code\n  File \"/usr/lib/python3.11/unittest/__main__.py\", line 18, in <module>\n    main(module=None)\n  File \"/usr/lib/python3.11/unittest/main.py\", line 101, in __init__\n    self.parseArgs(argv)\n  File \"/usr/lib/python3.11/unittest/main.py\", line 150, in parseArgs\n    self.createTests()\n  File \"/usr/lib/python3.11/unittest/main.py\", line 161, in createTests\n    self.test = self.testLoader.loadTestsFromNames(self.testNames,\n                ^^^^^^^^^^^^^^^^^^^^^^^^^^^^^^^^^^^^^^^^^^^^^^^^^^\n  File \"/usr/lib/python3.11/unittest/loader.py\", line 220, in loadTestsFromNames\n    suites = [self.loadTestsFromName(name, module) for name in names]\n             ^^^^^^^^^^^^^^^^^^^^^^^^^^^^^^^^^^^^^^^^^^^^^^^^^^^^^^^^\n  File \"/usr/lib/python3.11/unittest/loader.py\", line 220, in <listcomp>\n    suites = [self.loadTestsFromName(name, module) for name in names]\n              ^^^^^^^^^^^^^^^^^^^^^^^^^^^^^^^^^^^^\n  File \"/usr/lib/python3.11/unittest/loader.py\", line 154, in loadTestsFromName\n    module = __import__(module_name)\n             ^^^^^^^^^^^^^^^^^^^^^^^\n  File \"/opt/powerautomation/mcp/adapter/development_intervention_mcp/integration_tests/__init__.py\", line 1\n    \"\"\"测试模块初始化文件\"\"\"\\n\n                                      ^\nSyntaxError: unexpected character after line continuation character\n",
      "return_code": 1
    },
    {
      "module_name": "directory_structure_mcp",
      "test_type": "unit",
      "test_file": "test_directory_structure_mcp.py",
      "test_path": "mcp/adapter/directory_structure_mcp/unit_tests/test_directory_structure_mcp.py",
      "status": "FAIL",
      "duration": 0.049877,
      "start_time": "2025-06-17T06:01:49.284260",
      "end_time": "2025-06-17T06:01:49.334137",
      "stdout": "",
      "stderr": "Traceback (most recent call last):\n  File \"<frozen runpy>\", line 198, in _run_module_as_main\n  File \"<frozen runpy>\", line 88, in _run_code\n  File \"/usr/lib/python3.11/unittest/__main__.py\", line 18, in <module>\n    main(module=None)\n  File \"/usr/lib/python3.11/unittest/main.py\", line 101, in __init__\n    self.parseArgs(argv)\n  File \"/usr/lib/python3.11/unittest/main.py\", line 150, in parseArgs\n    self.createTests()\n  File \"/usr/lib/python3.11/unittest/main.py\", line 161, in createTests\n    self.test = self.testLoader.loadTestsFromNames(self.testNames,\n                ^^^^^^^^^^^^^^^^^^^^^^^^^^^^^^^^^^^^^^^^^^^^^^^^^^\n  File \"/usr/lib/python3.11/unittest/loader.py\", line 220, in loadTestsFromNames\n    suites = [self.loadTestsFromName(name, module) for name in names]\n             ^^^^^^^^^^^^^^^^^^^^^^^^^^^^^^^^^^^^^^^^^^^^^^^^^^^^^^^^\n  File \"/usr/lib/python3.11/unittest/loader.py\", line 220, in <listcomp>\n    suites = [self.loadTestsFromName(name, module) for name in names]\n              ^^^^^^^^^^^^^^^^^^^^^^^^^^^^^^^^^^^^\n  File \"/usr/lib/python3.11/unittest/loader.py\", line 154, in loadTestsFromName\n    module = __import__(module_name)\n             ^^^^^^^^^^^^^^^^^^^^^^^\n  File \"/opt/powerautomation/mcp/adapter/directory_structure_mcp/unit_tests/__init__.py\", line 1\n    \"\"\"测试模块初始化文件\"\"\"\\n\n                                      ^\nSyntaxError: unexpected character after line continuation character\n",
      "return_code": 1
    },
    {
      "module_name": "directory_structure_mcp",
      "test_type": "integration",
      "test_file": "test_directory_structure_mcp_integration.py",
      "test_path": "mcp/adapter/directory_structure_mcp/integration_tests/test_directory_structure_mcp_integration.py",
      "status": "FAIL",
      "duration": 0.049889,
      "start_time": "2025-06-17T06:01:49.334269",
      "end_time": "2025-06-17T06:01:49.384158",
      "stdout": "",
      "stderr": "Traceback (most recent call last):\n  File \"<frozen runpy>\", line 198, in _run_module_as_main\n  File \"<frozen runpy>\", line 88, in _run_code\n  File \"/usr/lib/python3.11/unittest/__main__.py\", line 18, in <module>\n    main(module=None)\n  File \"/usr/lib/python3.11/unittest/main.py\", line 101, in __init__\n    self.parseArgs(argv)\n  File \"/usr/lib/python3.11/unittest/main.py\", line 150, in parseArgs\n    self.createTests()\n  File \"/usr/lib/python3.11/unittest/main.py\", line 161, in createTests\n    self.test = self.testLoader.loadTestsFromNames(self.testNames,\n                ^^^^^^^^^^^^^^^^^^^^^^^^^^^^^^^^^^^^^^^^^^^^^^^^^^\n  File \"/usr/lib/python3.11/unittest/loader.py\", line 220, in loadTestsFromNames\n    suites = [self.loadTestsFromName(name, module) for name in names]\n             ^^^^^^^^^^^^^^^^^^^^^^^^^^^^^^^^^^^^^^^^^^^^^^^^^^^^^^^^\n  File \"/usr/lib/python3.11/unittest/loader.py\", line 220, in <listcomp>\n    suites = [self.loadTestsFromName(name, module) for name in names]\n              ^^^^^^^^^^^^^^^^^^^^^^^^^^^^^^^^^^^^\n  File \"/usr/lib/python3.11/unittest/loader.py\", line 154, in loadTestsFromName\n    module = __import__(module_name)\n             ^^^^^^^^^^^^^^^^^^^^^^^\n  File \"/opt/powerautomation/mcp/adapter/directory_structure_mcp/integration_tests/__init__.py\", line 1\n    \"\"\"测试模块初始化文件\"\"\"\\n\n                                      ^\nSyntaxError: unexpected character after line continuation character\n",
      "return_code": 1
    },
    {
      "module_name": "enterprise_smartui_mcp",
      "test_type": "unit",
      "test_file": "test_enterprise_smartui_mcp.py",
      "test_path": "mcp/adapter/enterprise_smartui_mcp/unit_tests/test_enterprise_smartui_mcp.py",
      "status": "FAIL",
      "duration": 0.049883,
      "start_time": "2025-06-17T06:01:49.384307",
      "end_time": "2025-06-17T06:01:49.434190",
      "stdout": "",
      "stderr": "Traceback (most recent call last):\n  File \"<frozen runpy>\", line 198, in _run_module_as_main\n  File \"<frozen runpy>\", line 88, in _run_code\n  File \"/usr/lib/python3.11/unittest/__main__.py\", line 18, in <module>\n    main(module=None)\n  File \"/usr/lib/python3.11/unittest/main.py\", line 101, in __init__\n    self.parseArgs(argv)\n  File \"/usr/lib/python3.11/unittest/main.py\", line 150, in parseArgs\n    self.createTests()\n  File \"/usr/lib/python3.11/unittest/main.py\", line 161, in createTests\n    self.test = self.testLoader.loadTestsFromNames(self.testNames,\n                ^^^^^^^^^^^^^^^^^^^^^^^^^^^^^^^^^^^^^^^^^^^^^^^^^^\n  File \"/usr/lib/python3.11/unittest/loader.py\", line 220, in loadTestsFromNames\n    suites = [self.loadTestsFromName(name, module) for name in names]\n             ^^^^^^^^^^^^^^^^^^^^^^^^^^^^^^^^^^^^^^^^^^^^^^^^^^^^^^^^\n  File \"/usr/lib/python3.11/unittest/loader.py\", line 220, in <listcomp>\n    suites = [self.loadTestsFromName(name, module) for name in names]\n              ^^^^^^^^^^^^^^^^^^^^^^^^^^^^^^^^^^^^\n  File \"/usr/lib/python3.11/unittest/loader.py\", line 154, in loadTestsFromName\n    module = __import__(module_name)\n             ^^^^^^^^^^^^^^^^^^^^^^^\n  File \"/opt/powerautomation/mcp/adapter/enterprise_smartui_mcp/unit_tests/__init__.py\", line 1\n    \"\"\"测试模块初始化文件\"\"\"\\n\n                                      ^\nSyntaxError: unexpected character after line continuation character\n",
      "return_code": 1
    },
    {
      "module_name": "enterprise_smartui_mcp",
      "test_type": "integration",
      "test_file": "test_enterprise_smartui_mcp_integration.py",
      "test_path": "mcp/adapter/enterprise_smartui_mcp/integration_tests/test_enterprise_smartui_mcp_integration.py",
      "status": "FAIL",
      "duration": 0.048663,
      "start_time": "2025-06-17T06:01:49.434340",
      "end_time": "2025-06-17T06:01:49.483003",
      "stdout": "",
      "stderr": "Traceback (most recent call last):\n  File \"<frozen runpy>\", line 198, in _run_module_as_main\n  File \"<frozen runpy>\", line 88, in _run_code\n  File \"/usr/lib/python3.11/unittest/__main__.py\", line 18, in <module>\n    main(module=None)\n  File \"/usr/lib/python3.11/unittest/main.py\", line 101, in __init__\n    self.parseArgs(argv)\n  File \"/usr/lib/python3.11/unittest/main.py\", line 150, in parseArgs\n    self.createTests()\n  File \"/usr/lib/python3.11/unittest/main.py\", line 161, in createTests\n    self.test = self.testLoader.loadTestsFromNames(self.testNames,\n                ^^^^^^^^^^^^^^^^^^^^^^^^^^^^^^^^^^^^^^^^^^^^^^^^^^\n  File \"/usr/lib/python3.11/unittest/loader.py\", line 220, in loadTestsFromNames\n    suites = [self.loadTestsFromName(name, module) for name in names]\n             ^^^^^^^^^^^^^^^^^^^^^^^^^^^^^^^^^^^^^^^^^^^^^^^^^^^^^^^^\n  File \"/usr/lib/python3.11/unittest/loader.py\", line 220, in <listcomp>\n    suites = [self.loadTestsFromName(name, module) for name in names]\n              ^^^^^^^^^^^^^^^^^^^^^^^^^^^^^^^^^^^^\n  File \"/usr/lib/python3.11/unittest/loader.py\", line 154, in loadTestsFromName\n    module = __import__(module_name)\n             ^^^^^^^^^^^^^^^^^^^^^^^\n  File \"/opt/powerautomation/mcp/adapter/enterprise_smartui_mcp/integration_tests/__init__.py\", line 1\n    \"\"\"测试模块初始化文件\"\"\"\\n\n                                      ^\nSyntaxError: unexpected character after line continuation character\n",
      "return_code": 1
    },
    {
      "module_name": "github_mcp",
      "test_type": "unit",
      "test_file": "test_github_mcp.py",
      "test_path": "mcp/adapter/github_mcp/unit_tests/test_github_mcp.py",
      "status": "FAIL",
      "duration": 0.051429,
      "start_time": "2025-06-17T06:01:49.483145",
      "end_time": "2025-06-17T06:01:49.534574",
      "stdout": "",
      "stderr": "Traceback (most recent call last):\n  File \"<frozen runpy>\", line 198, in _run_module_as_main\n  File \"<frozen runpy>\", line 88, in _run_code\n  File \"/usr/lib/python3.11/unittest/__main__.py\", line 18, in <module>\n    main(module=None)\n  File \"/usr/lib/python3.11/unittest/main.py\", line 101, in __init__\n    self.parseArgs(argv)\n  File \"/usr/lib/python3.11/unittest/main.py\", line 150, in parseArgs\n    self.createTests()\n  File \"/usr/lib/python3.11/unittest/main.py\", line 161, in createTests\n    self.test = self.testLoader.loadTestsFromNames(self.testNames,\n                ^^^^^^^^^^^^^^^^^^^^^^^^^^^^^^^^^^^^^^^^^^^^^^^^^^\n  File \"/usr/lib/python3.11/unittest/loader.py\", line 220, in loadTestsFromNames\n    suites = [self.loadTestsFromName(name, module) for name in names]\n             ^^^^^^^^^^^^^^^^^^^^^^^^^^^^^^^^^^^^^^^^^^^^^^^^^^^^^^^^\n  File \"/usr/lib/python3.11/unittest/loader.py\", line 220, in <listcomp>\n    suites = [self.loadTestsFromName(name, module) for name in names]\n              ^^^^^^^^^^^^^^^^^^^^^^^^^^^^^^^^^^^^\n  File \"/usr/lib/python3.11/unittest/loader.py\", line 154, in loadTestsFromName\n    module = __import__(module_name)\n             ^^^^^^^^^^^^^^^^^^^^^^^\n  File \"/opt/powerautomation/mcp/adapter/github_mcp/unit_tests/__init__.py\", line 1\n    \"\"\"测试模块初始化文件\"\"\"\\n\n                                      ^\nSyntaxError: unexpected character after line continuation character\n",
      "return_code": 1
    },
    {
      "module_name": "github_mcp",
      "test_type": "integration",
      "test_file": "test_github_mcp_integration.py",
      "test_path": "mcp/adapter/github_mcp/integration_tests/test_github_mcp_integration.py",
      "status": "FAIL",
      "duration": 0.048284,
      "start_time": "2025-06-17T06:01:49.534723",
      "end_time": "2025-06-17T06:01:49.583007",
      "stdout": "",
      "stderr": "Traceback (most recent call last):\n  File \"<frozen runpy>\", line 198, in _run_module_as_main\n  File \"<frozen runpy>\", line 88, in _run_code\n  File \"/usr/lib/python3.11/unittest/__main__.py\", line 18, in <module>\n    main(module=None)\n  File \"/usr/lib/python3.11/unittest/main.py\", line 101, in __init__\n    self.parseArgs(argv)\n  File \"/usr/lib/python3.11/unittest/main.py\", line 150, in parseArgs\n    self.createTests()\n  File \"/usr/lib/python3.11/unittest/main.py\", line 161, in createTests\n    self.test = self.testLoader.loadTestsFromNames(self.testNames,\n                ^^^^^^^^^^^^^^^^^^^^^^^^^^^^^^^^^^^^^^^^^^^^^^^^^^\n  File \"/usr/lib/python3.11/unittest/loader.py\", line 220, in loadTestsFromNames\n    suites = [self.loadTestsFromName(name, module) for name in names]\n             ^^^^^^^^^^^^^^^^^^^^^^^^^^^^^^^^^^^^^^^^^^^^^^^^^^^^^^^^\n  File \"/usr/lib/python3.11/unittest/loader.py\", line 220, in <listcomp>\n    suites = [self.loadTestsFromName(name, module) for name in names]\n              ^^^^^^^^^^^^^^^^^^^^^^^^^^^^^^^^^^^^\n  File \"/usr/lib/python3.11/unittest/loader.py\", line 154, in loadTestsFromName\n    module = __import__(module_name)\n             ^^^^^^^^^^^^^^^^^^^^^^^\n  File \"/opt/powerautomation/mcp/adapter/github_mcp/integration_tests/__init__.py\", line 1\n    \"\"\"测试模块初始化文件\"\"\"\\n\n                                      ^\nSyntaxError: unexpected character after line continuation character\n",
      "return_code": 1
    },
    {
      "module_name": "interaction_log_manager",
      "test_type": "unit",
      "test_file": "test_interaction_log_manager.py",
      "test_path": "mcp/adapter/interaction_log_manager/unit_tests/test_interaction_log_manager.py",
      "status": "FAIL",
      "duration": 0.050249,
      "start_time": "2025-06-17T06:01:49.583146",
      "end_time": "2025-06-17T06:01:49.633395",
      "stdout": "",
      "stderr": "Traceback (most recent call last):\n  File \"<frozen runpy>\", line 198, in _run_module_as_main\n  File \"<frozen runpy>\", line 88, in _run_code\n  File \"/usr/lib/python3.11/unittest/__main__.py\", line 18, in <module>\n    main(module=None)\n  File \"/usr/lib/python3.11/unittest/main.py\", line 101, in __init__\n    self.parseArgs(argv)\n  File \"/usr/lib/python3.11/unittest/main.py\", line 150, in parseArgs\n    self.createTests()\n  File \"/usr/lib/python3.11/unittest/main.py\", line 161, in createTests\n    self.test = self.testLoader.loadTestsFromNames(self.testNames,\n                ^^^^^^^^^^^^^^^^^^^^^^^^^^^^^^^^^^^^^^^^^^^^^^^^^^\n  File \"/usr/lib/python3.11/unittest/loader.py\", line 220, in loadTestsFromNames\n    suites = [self.loadTestsFromName(name, module) for name in names]\n             ^^^^^^^^^^^^^^^^^^^^^^^^^^^^^^^^^^^^^^^^^^^^^^^^^^^^^^^^\n  File \"/usr/lib/python3.11/unittest/loader.py\", line 220, in <listcomp>\n    suites = [self.loadTestsFromName(name, module) for name in names]\n              ^^^^^^^^^^^^^^^^^^^^^^^^^^^^^^^^^^^^\n  File \"/usr/lib/python3.11/unittest/loader.py\", line 154, in loadTestsFromName\n    module = __import__(module_name)\n             ^^^^^^^^^^^^^^^^^^^^^^^\n  File \"/opt/powerautomation/mcp/adapter/interaction_log_manager/unit_tests/__init__.py\", line 1\n    \"\"\"测试模块初始化文件\"\"\"\\n\n                                      ^\nSyntaxError: unexpected character after line continuation character\n",
      "return_code": 1
    },
    {
      "module_name": "interaction_log_manager",
      "test_type": "integration",
      "test_file": "test_interaction_log_manager_integration.py",
      "test_path": "mcp/adapter/interaction_log_manager/integration_tests/test_interaction_log_manager_integration.py",
      "status": "FAIL",
      "duration": 0.057924,
      "start_time": "2025-06-17T06:01:49.633527",
      "end_time": "2025-06-17T06:01:49.691451",
      "stdout": "",
      "stderr": "Traceback (most recent call last):\n  File \"<frozen runpy>\", line 198, in _run_module_as_main\n  File \"<frozen runpy>\", line 88, in _run_code\n  File \"/usr/lib/python3.11/unittest/__main__.py\", line 18, in <module>\n    main(module=None)\n  File \"/usr/lib/python3.11/unittest/main.py\", line 101, in __init__\n    self.parseArgs(argv)\n  File \"/usr/lib/python3.11/unittest/main.py\", line 150, in parseArgs\n    self.createTests()\n  File \"/usr/lib/python3.11/unittest/main.py\", line 161, in createTests\n    self.test = self.testLoader.loadTestsFromNames(self.testNames,\n                ^^^^^^^^^^^^^^^^^^^^^^^^^^^^^^^^^^^^^^^^^^^^^^^^^^\n  File \"/usr/lib/python3.11/unittest/loader.py\", line 220, in loadTestsFromNames\n    suites = [self.loadTestsFromName(name, module) for name in names]\n             ^^^^^^^^^^^^^^^^^^^^^^^^^^^^^^^^^^^^^^^^^^^^^^^^^^^^^^^^\n  File \"/usr/lib/python3.11/unittest/loader.py\", line 220, in <listcomp>\n    suites = [self.loadTestsFromName(name, module) for name in names]\n              ^^^^^^^^^^^^^^^^^^^^^^^^^^^^^^^^^^^^\n  File \"/usr/lib/python3.11/unittest/loader.py\", line 154, in loadTestsFromName\n    module = __import__(module_name)\n             ^^^^^^^^^^^^^^^^^^^^^^^\n  File \"/opt/powerautomation/mcp/adapter/interaction_log_manager/integration_tests/__init__.py\", line 1\n    \"\"\"测试模块初始化文件\"\"\"\\n\n                                      ^\nSyntaxError: unexpected character after line continuation character\n",
      "return_code": 1
    },
    {
      "module_name": "test_manage_mcp",
      "test_type": "unit",
      "test_file": "test_test_manage_mcp.py",
      "test_path": "mcp/adapter/test_manage_mcp/unit_tests/test_test_manage_mcp.py",
      "status": "FAIL",
      "duration": 0.10567,
      "start_time": "2025-06-17T06:01:49.691576",
      "end_time": "2025-06-17T06:01:49.797246",
      "stdout": "",
      "stderr": "Traceback (most recent call last):\n  File \"<frozen runpy>\", line 198, in _run_module_as_main\n  File \"<frozen runpy>\", line 88, in _run_code\n  File \"/usr/lib/python3.11/unittest/__main__.py\", line 18, in <module>\n    main(module=None)\n  File \"/usr/lib/python3.11/unittest/main.py\", line 101, in __init__\n    self.parseArgs(argv)\n  File \"/usr/lib/python3.11/unittest/main.py\", line 150, in parseArgs\n    self.createTests()\n  File \"/usr/lib/python3.11/unittest/main.py\", line 161, in createTests\n    self.test = self.testLoader.loadTestsFromNames(self.testNames,\n                ^^^^^^^^^^^^^^^^^^^^^^^^^^^^^^^^^^^^^^^^^^^^^^^^^^\n  File \"/usr/lib/python3.11/unittest/loader.py\", line 220, in loadTestsFromNames\n    suites = [self.loadTestsFromName(name, module) for name in names]\n             ^^^^^^^^^^^^^^^^^^^^^^^^^^^^^^^^^^^^^^^^^^^^^^^^^^^^^^^^\n  File \"/usr/lib/python3.11/unittest/loader.py\", line 220, in <listcomp>\n    suites = [self.loadTestsFromName(name, module) for name in names]\n              ^^^^^^^^^^^^^^^^^^^^^^^^^^^^^^^^^^^^\n  File \"/usr/lib/python3.11/unittest/loader.py\", line 154, in loadTestsFromName\n    module = __import__(module_name)\n             ^^^^^^^^^^^^^^^^^^^^^^^\n  File \"/opt/powerautomation/mcp/adapter/test_manage_mcp/unit_tests/__init__.py\", line 1\n    \"\"\"测试模块初始化文件\"\"\"\\n\n                                      ^\nSyntaxError: unexpected character after line continuation character\n",
      "return_code": 1
    },
    {
      "module_name": "test_manage_mcp",
      "test_type": "integration",
      "test_file": "test_test_manage_mcp_integration.py",
      "test_path": "mcp/adapter/test_manage_mcp/integration_tests/test_test_manage_mcp_integration.py",
      "status": "FAIL",
      "duration": 0.105533,
      "start_time": "2025-06-17T06:01:49.797365",
      "end_time": "2025-06-17T06:01:49.902898",
      "stdout": "",
      "stderr": "Traceback (most recent call last):\n  File \"<frozen runpy>\", line 198, in _run_module_as_main\n  File \"<frozen runpy>\", line 88, in _run_code\n  File \"/usr/lib/python3.11/unittest/__main__.py\", line 18, in <module>\n    main(module=None)\n  File \"/usr/lib/python3.11/unittest/main.py\", line 101, in __init__\n    self.parseArgs(argv)\n  File \"/usr/lib/python3.11/unittest/main.py\", line 150, in parseArgs\n    self.createTests()\n  File \"/usr/lib/python3.11/unittest/main.py\", line 161, in createTests\n    self.test = self.testLoader.loadTestsFromNames(self.testNames,\n                ^^^^^^^^^^^^^^^^^^^^^^^^^^^^^^^^^^^^^^^^^^^^^^^^^^\n  File \"/usr/lib/python3.11/unittest/loader.py\", line 220, in loadTestsFromNames\n    suites = [self.loadTestsFromName(name, module) for name in names]\n             ^^^^^^^^^^^^^^^^^^^^^^^^^^^^^^^^^^^^^^^^^^^^^^^^^^^^^^^^\n  File \"/usr/lib/python3.11/unittest/loader.py\", line 220, in <listcomp>\n    suites = [self.loadTestsFromName(name, module) for name in names]\n              ^^^^^^^^^^^^^^^^^^^^^^^^^^^^^^^^^^^^\n  File \"/usr/lib/python3.11/unittest/loader.py\", line 154, in loadTestsFromName\n    module = __import__(module_name)\n             ^^^^^^^^^^^^^^^^^^^^^^^\n  File \"/opt/powerautomation/mcp/adapter/test_manage_mcp/integration_tests/__init__.py\", line 1\n    \"\"\"测试模块初始化文件\"\"\"\\n\n                                      ^\nSyntaxError: unexpected character after line continuation character\n",
      "return_code": 1
    },
    {
      "module_name": "kilocode_mcp",
      "test_type": "unit",
      "test_file": "test_kilocode_mcp.py",
      "test_path": "mcp/adapter/kilocode_mcp/unit_tests/test_kilocode_mcp.py",
      "status": "FAIL",
      "duration": 0.055462,
      "start_time": "2025-06-17T06:01:49.903036",
      "end_time": "2025-06-17T06:01:49.958498",
      "stdout": "",
      "stderr": "Traceback (most recent call last):\n  File \"<frozen runpy>\", line 198, in _run_module_as_main\n  File \"<frozen runpy>\", line 88, in _run_code\n  File \"/usr/lib/python3.11/unittest/__main__.py\", line 18, in <module>\n    main(module=None)\n  File \"/usr/lib/python3.11/unittest/main.py\", line 101, in __init__\n    self.parseArgs(argv)\n  File \"/usr/lib/python3.11/unittest/main.py\", line 150, in parseArgs\n    self.createTests()\n  File \"/usr/lib/python3.11/unittest/main.py\", line 161, in createTests\n    self.test = self.testLoader.loadTestsFromNames(self.testNames,\n                ^^^^^^^^^^^^^^^^^^^^^^^^^^^^^^^^^^^^^^^^^^^^^^^^^^\n  File \"/usr/lib/python3.11/unittest/loader.py\", line 220, in loadTestsFromNames\n    suites = [self.loadTestsFromName(name, module) for name in names]\n             ^^^^^^^^^^^^^^^^^^^^^^^^^^^^^^^^^^^^^^^^^^^^^^^^^^^^^^^^\n  File \"/usr/lib/python3.11/unittest/loader.py\", line 220, in <listcomp>\n    suites = [self.loadTestsFromName(name, module) for name in names]\n              ^^^^^^^^^^^^^^^^^^^^^^^^^^^^^^^^^^^^\n  File \"/usr/lib/python3.11/unittest/loader.py\", line 154, in loadTestsFromName\n    module = __import__(module_name)\n             ^^^^^^^^^^^^^^^^^^^^^^^\n  File \"/opt/powerautomation/mcp/adapter/kilocode_mcp/unit_tests/__init__.py\", line 1\n    \"\"\"测试模块初始化文件\"\"\"\\n\n                                      ^\nSyntaxError: unexpected character after line continuation character\n",
      "return_code": 1
    },
    {
      "module_name": "kilocode_mcp",
      "test_type": "integration",
      "test_file": "test_kilocode_mcp_integration.py",
      "test_path": "mcp/adapter/kilocode_mcp/integration_tests/test_kilocode_mcp_integration.py",
      "status": "FAIL",
      "duration": 0.052374,
      "start_time": "2025-06-17T06:01:49.958636",
      "end_time": "2025-06-17T06:01:50.011010",
      "stdout": "",
      "stderr": "Traceback (most recent call last):\n  File \"<frozen runpy>\", line 198, in _run_module_as_main\n  File \"<frozen runpy>\", line 88, in _run_code\n  File \"/usr/lib/python3.11/unittest/__main__.py\", line 18, in <module>\n    main(module=None)\n  File \"/usr/lib/python3.11/unittest/main.py\", line 101, in __init__\n    self.parseArgs(argv)\n  File \"/usr/lib/python3.11/unittest/main.py\", line 150, in parseArgs\n    self.createTests()\n  File \"/usr/lib/python3.11/unittest/main.py\", line 161, in createTests\n    self.test = self.testLoader.loadTestsFromNames(self.testNames,\n                ^^^^^^^^^^^^^^^^^^^^^^^^^^^^^^^^^^^^^^^^^^^^^^^^^^\n  File \"/usr/lib/python3.11/unittest/loader.py\", line 220, in loadTestsFromNames\n    suites = [self.loadTestsFromName(name, module) for name in names]\n             ^^^^^^^^^^^^^^^^^^^^^^^^^^^^^^^^^^^^^^^^^^^^^^^^^^^^^^^^\n  File \"/usr/lib/python3.11/unittest/loader.py\", line 220, in <listcomp>\n    suites = [self.loadTestsFromName(name, module) for name in names]\n              ^^^^^^^^^^^^^^^^^^^^^^^^^^^^^^^^^^^^\n  File \"/usr/lib/python3.11/unittest/loader.py\", line 154, in loadTestsFromName\n    module = __import__(module_name)\n             ^^^^^^^^^^^^^^^^^^^^^^^\n  File \"/opt/powerautomation/mcp/adapter/kilocode_mcp/integration_tests/__init__.py\", line 1\n    \"\"\"测试模块初始化文件\"\"\"\\n\n                                      ^\nSyntaxError: unexpected character after line continuation character\n",
      "return_code": 1
    },
    {
      "module_name": "local_model_mcp",
      "test_type": "unit",
      "test_file": "test_local_model_mcp.py",
      "test_path": "mcp/adapter/local_model_mcp/unit_tests/test_local_model_mcp.py",
      "status": "FAIL",
      "duration": 2.248424,
      "start_time": "2025-06-17T06:01:50.011130",
      "end_time": "2025-06-17T06:01:52.259554",
      "stdout": "",
      "stderr": "Traceback (most recent call last):\n  File \"<frozen runpy>\", line 198, in _run_module_as_main\n  File \"<frozen runpy>\", line 88, in _run_code\n  File \"/usr/lib/python3.11/unittest/__main__.py\", line 18, in <module>\n    main(module=None)\n  File \"/usr/lib/python3.11/unittest/main.py\", line 101, in __init__\n    self.parseArgs(argv)\n  File \"/usr/lib/python3.11/unittest/main.py\", line 150, in parseArgs\n    self.createTests()\n  File \"/usr/lib/python3.11/unittest/main.py\", line 161, in createTests\n    self.test = self.testLoader.loadTestsFromNames(self.testNames,\n                ^^^^^^^^^^^^^^^^^^^^^^^^^^^^^^^^^^^^^^^^^^^^^^^^^^\n  File \"/usr/lib/python3.11/unittest/loader.py\", line 220, in loadTestsFromNames\n    suites = [self.loadTestsFromName(name, module) for name in names]\n             ^^^^^^^^^^^^^^^^^^^^^^^^^^^^^^^^^^^^^^^^^^^^^^^^^^^^^^^^\n  File \"/usr/lib/python3.11/unittest/loader.py\", line 220, in <listcomp>\n    suites = [self.loadTestsFromName(name, module) for name in names]\n              ^^^^^^^^^^^^^^^^^^^^^^^^^^^^^^^^^^^^\n  File \"/usr/lib/python3.11/unittest/loader.py\", line 154, in loadTestsFromName\n    module = __import__(module_name)\n             ^^^^^^^^^^^^^^^^^^^^^^^\n  File \"/opt/powerautomation/mcp/adapter/local_model_mcp/unit_tests/__init__.py\", line 1\n    \"\"\"测试模块初始化文件\"\"\"\\n\n                                      ^\nSyntaxError: unexpected character after line continuation character\n",
      "return_code": 1
    },
    {
      "module_name": "local_model_mcp",
      "test_type": "integration",
      "test_file": "test_local_model_mcp_integration.py",
      "test_path": "mcp/adapter/local_model_mcp/integration_tests/test_local_model_mcp_integration.py",
      "status": "FAIL",
      "duration": 2.256802,
      "start_time": "2025-06-17T06:01:52.259686",
      "end_time": "2025-06-17T06:01:54.516488",
      "stdout": "",
      "stderr": "Traceback (most recent call last):\n  File \"<frozen runpy>\", line 198, in _run_module_as_main\n  File \"<frozen runpy>\", line 88, in _run_code\n  File \"/usr/lib/python3.11/unittest/__main__.py\", line 18, in <module>\n    main(module=None)\n  File \"/usr/lib/python3.11/unittest/main.py\", line 101, in __init__\n    self.parseArgs(argv)\n  File \"/usr/lib/python3.11/unittest/main.py\", line 150, in parseArgs\n    self.createTests()\n  File \"/usr/lib/python3.11/unittest/main.py\", line 161, in createTests\n    self.test = self.testLoader.loadTestsFromNames(self.testNames,\n                ^^^^^^^^^^^^^^^^^^^^^^^^^^^^^^^^^^^^^^^^^^^^^^^^^^\n  File \"/usr/lib/python3.11/unittest/loader.py\", line 220, in loadTestsFromNames\n    suites = [self.loadTestsFromName(name, module) for name in names]\n             ^^^^^^^^^^^^^^^^^^^^^^^^^^^^^^^^^^^^^^^^^^^^^^^^^^^^^^^^\n  File \"/usr/lib/python3.11/unittest/loader.py\", line 220, in <listcomp>\n    suites = [self.loadTestsFromName(name, module) for name in names]\n              ^^^^^^^^^^^^^^^^^^^^^^^^^^^^^^^^^^^^\n  File \"/usr/lib/python3.11/unittest/loader.py\", line 154, in loadTestsFromName\n    module = __import__(module_name)\n             ^^^^^^^^^^^^^^^^^^^^^^^\n  File \"/opt/powerautomation/mcp/adapter/local_model_mcp/integration_tests/__init__.py\", line 1\n    \"\"\"测试模块初始化文件\"\"\"\\n\n                                      ^\nSyntaxError: unexpected character after line continuation character\n",
      "return_code": 1
    },
    {
      "module_name": "enhanced_workflow_mcp",
      "test_type": "unit",
      "test_file": "test_enhanced_workflow_mcp.py",
      "test_path": "mcp/adapter/enhanced_workflow_mcp/unit_tests/test_enhanced_workflow_mcp.py",
      "status": "FAIL",
      "duration": 0.245848,
      "start_time": "2025-06-17T06:01:54.516621",
      "end_time": "2025-06-17T06:01:54.762469",
      "stdout": "",
      "stderr": "Traceback (most recent call last):\n  File \"<frozen runpy>\", line 198, in _run_module_as_main\n  File \"<frozen runpy>\", line 88, in _run_code\n  File \"/usr/lib/python3.11/unittest/__main__.py\", line 18, in <module>\n    main(module=None)\n  File \"/usr/lib/python3.11/unittest/main.py\", line 101, in __init__\n    self.parseArgs(argv)\n  File \"/usr/lib/python3.11/unittest/main.py\", line 150, in parseArgs\n    self.createTests()\n  File \"/usr/lib/python3.11/unittest/main.py\", line 161, in createTests\n    self.test = self.testLoader.loadTestsFromNames(self.testNames,\n                ^^^^^^^^^^^^^^^^^^^^^^^^^^^^^^^^^^^^^^^^^^^^^^^^^^\n  File \"/usr/lib/python3.11/unittest/loader.py\", line 220, in loadTestsFromNames\n    suites = [self.loadTestsFromName(name, module) for name in names]\n             ^^^^^^^^^^^^^^^^^^^^^^^^^^^^^^^^^^^^^^^^^^^^^^^^^^^^^^^^\n  File \"/usr/lib/python3.11/unittest/loader.py\", line 220, in <listcomp>\n    suites = [self.loadTestsFromName(name, module) for name in names]\n              ^^^^^^^^^^^^^^^^^^^^^^^^^^^^^^^^^^^^\n  File \"/usr/lib/python3.11/unittest/loader.py\", line 154, in loadTestsFromName\n    module = __import__(module_name)\n             ^^^^^^^^^^^^^^^^^^^^^^^\n  File \"/opt/powerautomation/mcp/adapter/enhanced_workflow_mcp/unit_tests/__init__.py\", line 1\n    \"\"\"测试模块初始化文件\"\"\"\\n\n                                      ^\nSyntaxError: unexpected character after line continuation character\n",
      "return_code": 1
    },
    {
      "module_name": "enhanced_workflow_mcp",
      "test_type": "integration",
      "test_file": "test_enhanced_workflow_mcp_integration.py",
      "test_path": "mcp/adapter/enhanced_workflow_mcp/integration_tests/test_enhanced_workflow_mcp_integration.py",
      "status": "FAIL",
      "duration": 0.241742,
      "start_time": "2025-06-17T06:01:54.762612",
      "end_time": "2025-06-17T06:01:55.004354",
      "stdout": "",
      "stderr": "Traceback (most recent call last):\n  File \"<frozen runpy>\", line 198, in _run_module_as_main\n  File \"<frozen runpy>\", line 88, in _run_code\n  File \"/usr/lib/python3.11/unittest/__main__.py\", line 18, in <module>\n    main(module=None)\n  File \"/usr/lib/python3.11/unittest/main.py\", line 101, in __init__\n    self.parseArgs(argv)\n  File \"/usr/lib/python3.11/unittest/main.py\", line 150, in parseArgs\n    self.createTests()\n  File \"/usr/lib/python3.11/unittest/main.py\", line 161, in createTests\n    self.test = self.testLoader.loadTestsFromNames(self.testNames,\n                ^^^^^^^^^^^^^^^^^^^^^^^^^^^^^^^^^^^^^^^^^^^^^^^^^^\n  File \"/usr/lib/python3.11/unittest/loader.py\", line 220, in loadTestsFromNames\n    suites = [self.loadTestsFromName(name, module) for name in names]\n             ^^^^^^^^^^^^^^^^^^^^^^^^^^^^^^^^^^^^^^^^^^^^^^^^^^^^^^^^\n  File \"/usr/lib/python3.11/unittest/loader.py\", line 220, in <listcomp>\n    suites = [self.loadTestsFromName(name, module) for name in names]\n              ^^^^^^^^^^^^^^^^^^^^^^^^^^^^^^^^^^^^\n  File \"/usr/lib/python3.11/unittest/loader.py\", line 154, in loadTestsFromName\n    module = __import__(module_name)\n             ^^^^^^^^^^^^^^^^^^^^^^^\n  File \"/opt/powerautomation/mcp/adapter/enhanced_workflow_mcp/integration_tests/__init__.py\", line 1\n    \"\"\"测试模块初始化文件\"\"\"\\n\n                                      ^\nSyntaxError: unexpected character after line continuation character\n",
      "return_code": 1
    },
    {
      "module_name": "architecture_design_mcp",
      "test_type": "unit",
      "test_file": "test_architecture_design_mcp.py",
      "test_path": "mcp/workflow/architecture_design_mcp/unit_tests/test_architecture_design_mcp.py",
      "status": "FAIL",
      "duration": 0.047842,
      "start_time": "2025-06-17T06:01:55.004496",
      "end_time": "2025-06-17T06:01:55.052338",
      "stdout": "",
      "stderr": "Traceback (most recent call last):\n  File \"<frozen runpy>\", line 198, in _run_module_as_main\n  File \"<frozen runpy>\", line 88, in _run_code\n  File \"/usr/lib/python3.11/unittest/__main__.py\", line 18, in <module>\n    main(module=None)\n  File \"/usr/lib/python3.11/unittest/main.py\", line 101, in __init__\n    self.parseArgs(argv)\n  File \"/usr/lib/python3.11/unittest/main.py\", line 150, in parseArgs\n    self.createTests()\n  File \"/usr/lib/python3.11/unittest/main.py\", line 161, in createTests\n    self.test = self.testLoader.loadTestsFromNames(self.testNames,\n                ^^^^^^^^^^^^^^^^^^^^^^^^^^^^^^^^^^^^^^^^^^^^^^^^^^\n  File \"/usr/lib/python3.11/unittest/loader.py\", line 220, in loadTestsFromNames\n    suites = [self.loadTestsFromName(name, module) for name in names]\n             ^^^^^^^^^^^^^^^^^^^^^^^^^^^^^^^^^^^^^^^^^^^^^^^^^^^^^^^^\n  File \"/usr/lib/python3.11/unittest/loader.py\", line 220, in <listcomp>\n    suites = [self.loadTestsFromName(name, module) for name in names]\n              ^^^^^^^^^^^^^^^^^^^^^^^^^^^^^^^^^^^^\n  File \"/usr/lib/python3.11/unittest/loader.py\", line 154, in loadTestsFromName\n    module = __import__(module_name)\n             ^^^^^^^^^^^^^^^^^^^^^^^\n  File \"/opt/powerautomation/mcp/workflow/architecture_design_mcp/unit_tests/__init__.py\", line 1\n    \"\"\"测试模块初始化文件\"\"\"\\n\n                                      ^\nSyntaxError: unexpected character after line continuation character\n",
      "return_code": 1
    },
    {
      "module_name": "architecture_design_mcp",
      "test_type": "integration",
      "test_file": "test_architecture_design_mcp_integration.py",
      "test_path": "mcp/workflow/architecture_design_mcp/integration_tests/test_architecture_design_mcp_integration.py",
      "status": "FAIL",
      "duration": 0.0606,
      "start_time": "2025-06-17T06:01:55.052458",
      "end_time": "2025-06-17T06:01:55.113058",
      "stdout": "",
      "stderr": "Traceback (most recent call last):\n  File \"<frozen runpy>\", line 198, in _run_module_as_main\n  File \"<frozen runpy>\", line 88, in _run_code\n  File \"/usr/lib/python3.11/unittest/__main__.py\", line 18, in <module>\n    main(module=None)\n  File \"/usr/lib/python3.11/unittest/main.py\", line 101, in __init__\n    self.parseArgs(argv)\n  File \"/usr/lib/python3.11/unittest/main.py\", line 150, in parseArgs\n    self.createTests()\n  File \"/usr/lib/python3.11/unittest/main.py\", line 161, in createTests\n    self.test = self.testLoader.loadTestsFromNames(self.testNames,\n                ^^^^^^^^^^^^^^^^^^^^^^^^^^^^^^^^^^^^^^^^^^^^^^^^^^\n  File \"/usr/lib/python3.11/unittest/loader.py\", line 220, in loadTestsFromNames\n    suites = [self.loadTestsFromName(name, module) for name in names]\n             ^^^^^^^^^^^^^^^^^^^^^^^^^^^^^^^^^^^^^^^^^^^^^^^^^^^^^^^^\n  File \"/usr/lib/python3.11/unittest/loader.py\", line 220, in <listcomp>\n    suites = [self.loadTestsFromName(name, module) for name in names]\n              ^^^^^^^^^^^^^^^^^^^^^^^^^^^^^^^^^^^^\n  File \"/usr/lib/python3.11/unittest/loader.py\", line 154, in loadTestsFromName\n    module = __import__(module_name)\n             ^^^^^^^^^^^^^^^^^^^^^^^\n  File \"/opt/powerautomation/mcp/workflow/architecture_design_mcp/integration_tests/__init__.py\", line 1\n    \"\"\"测试模块初始化文件\"\"\"\\n\n                                      ^\nSyntaxError: unexpected character after line continuation character\n",
      "return_code": 1
    },
    {
      "module_name": "coding_workflow_mcp",
      "test_type": "unit",
      "test_file": "test_coding_workflow_mcp.py",
      "test_path": "mcp/workflow/coding_workflow_mcp/unit_tests/test_coding_workflow_mcp.py",
      "status": "FAIL",
      "duration": 0.050481,
      "start_time": "2025-06-17T06:01:55.113200",
      "end_time": "2025-06-17T06:01:55.163681",
      "stdout": "",
      "stderr": "Traceback (most recent call last):\n  File \"<frozen runpy>\", line 198, in _run_module_as_main\n  File \"<frozen runpy>\", line 88, in _run_code\n  File \"/usr/lib/python3.11/unittest/__main__.py\", line 18, in <module>\n    main(module=None)\n  File \"/usr/lib/python3.11/unittest/main.py\", line 101, in __init__\n    self.parseArgs(argv)\n  File \"/usr/lib/python3.11/unittest/main.py\", line 150, in parseArgs\n    self.createTests()\n  File \"/usr/lib/python3.11/unittest/main.py\", line 161, in createTests\n    self.test = self.testLoader.loadTestsFromNames(self.testNames,\n                ^^^^^^^^^^^^^^^^^^^^^^^^^^^^^^^^^^^^^^^^^^^^^^^^^^\n  File \"/usr/lib/python3.11/unittest/loader.py\", line 220, in loadTestsFromNames\n    suites = [self.loadTestsFromName(name, module) for name in names]\n             ^^^^^^^^^^^^^^^^^^^^^^^^^^^^^^^^^^^^^^^^^^^^^^^^^^^^^^^^\n  File \"/usr/lib/python3.11/unittest/loader.py\", line 220, in <listcomp>\n    suites = [self.loadTestsFromName(name, module) for name in names]\n              ^^^^^^^^^^^^^^^^^^^^^^^^^^^^^^^^^^^^\n  File \"/usr/lib/python3.11/unittest/loader.py\", line 154, in loadTestsFromName\n    module = __import__(module_name)\n             ^^^^^^^^^^^^^^^^^^^^^^^\n  File \"/opt/powerautomation/mcp/workflow/coding_workflow_mcp/unit_tests/__init__.py\", line 1\n    \"\"\"测试模块初始化文件\"\"\"\\n\n                                      ^\nSyntaxError: unexpected character after line continuation character\n",
      "return_code": 1
    },
    {
      "module_name": "coding_workflow_mcp",
      "test_type": "integration",
      "test_file": "test_coding_workflow_mcp_integration.py",
      "test_path": "mcp/workflow/coding_workflow_mcp/integration_tests/test_coding_workflow_mcp_integration.py",
      "status": "FAIL",
      "duration": 0.053516,
      "start_time": "2025-06-17T06:01:55.163834",
      "end_time": "2025-06-17T06:01:55.217350",
      "stdout": "",
      "stderr": "Traceback (most recent call last):\n  File \"<frozen runpy>\", line 198, in _run_module_as_main\n  File \"<frozen runpy>\", line 88, in _run_code\n  File \"/usr/lib/python3.11/unittest/__main__.py\", line 18, in <module>\n    main(module=None)\n  File \"/usr/lib/python3.11/unittest/main.py\", line 101, in __init__\n    self.parseArgs(argv)\n  File \"/usr/lib/python3.11/unittest/main.py\", line 150, in parseArgs\n    self.createTests()\n  File \"/usr/lib/python3.11/unittest/main.py\", line 161, in createTests\n    self.test = self.testLoader.loadTestsFromNames(self.testNames,\n                ^^^^^^^^^^^^^^^^^^^^^^^^^^^^^^^^^^^^^^^^^^^^^^^^^^\n  File \"/usr/lib/python3.11/unittest/loader.py\", line 220, in loadTestsFromNames\n    suites = [self.loadTestsFromName(name, module) for name in names]\n             ^^^^^^^^^^^^^^^^^^^^^^^^^^^^^^^^^^^^^^^^^^^^^^^^^^^^^^^^\n  File \"/usr/lib/python3.11/unittest/loader.py\", line 220, in <listcomp>\n    suites = [self.loadTestsFromName(name, module) for name in names]\n              ^^^^^^^^^^^^^^^^^^^^^^^^^^^^^^^^^^^^\n  File \"/usr/lib/python3.11/unittest/loader.py\", line 154, in loadTestsFromName\n    module = __import__(module_name)\n             ^^^^^^^^^^^^^^^^^^^^^^^\n  File \"/opt/powerautomation/mcp/workflow/coding_workflow_mcp/integration_tests/__init__.py\", line 1\n    \"\"\"测试模块初始化文件\"\"\"\\n\n                                      ^\nSyntaxError: unexpected character after line continuation character\n",
      "return_code": 1
    },
    {
      "module_name": "developer_flow_mcp",
      "test_type": "unit",
      "test_file": "test_developer_flow_mcp.py",
      "test_path": "mcp/workflow/developer_flow_mcp/unit_tests/test_developer_flow_mcp.py",
      "status": "FAIL",
      "duration": 0.053905,
      "start_time": "2025-06-17T06:01:55.217470",
      "end_time": "2025-06-17T06:01:55.271375",
      "stdout": "",
      "stderr": "Traceback (most recent call last):\n  File \"<frozen runpy>\", line 198, in _run_module_as_main\n  File \"<frozen runpy>\", line 88, in _run_code\n  File \"/usr/lib/python3.11/unittest/__main__.py\", line 18, in <module>\n    main(module=None)\n  File \"/usr/lib/python3.11/unittest/main.py\", line 101, in __init__\n    self.parseArgs(argv)\n  File \"/usr/lib/python3.11/unittest/main.py\", line 150, in parseArgs\n    self.createTests()\n  File \"/usr/lib/python3.11/unittest/main.py\", line 161, in createTests\n    self.test = self.testLoader.loadTestsFromNames(self.testNames,\n                ^^^^^^^^^^^^^^^^^^^^^^^^^^^^^^^^^^^^^^^^^^^^^^^^^^\n  File \"/usr/lib/python3.11/unittest/loader.py\", line 220, in loadTestsFromNames\n    suites = [self.loadTestsFromName(name, module) for name in names]\n             ^^^^^^^^^^^^^^^^^^^^^^^^^^^^^^^^^^^^^^^^^^^^^^^^^^^^^^^^\n  File \"/usr/lib/python3.11/unittest/loader.py\", line 220, in <listcomp>\n    suites = [self.loadTestsFromName(name, module) for name in names]\n              ^^^^^^^^^^^^^^^^^^^^^^^^^^^^^^^^^^^^\n  File \"/usr/lib/python3.11/unittest/loader.py\", line 154, in loadTestsFromName\n    module = __import__(module_name)\n             ^^^^^^^^^^^^^^^^^^^^^^^\n  File \"/opt/powerautomation/mcp/workflow/developer_flow_mcp/unit_tests/__init__.py\", line 1\n    \"\"\"测试模块初始化文件\"\"\"\\n\n                                      ^\nSyntaxError: unexpected character after line continuation character\n",
      "return_code": 1
    },
    {
      "module_name": "developer_flow_mcp",
      "test_type": "integration",
      "test_file": "test_developer_flow_mcp_integration.py",
      "test_path": "mcp/workflow/developer_flow_mcp/integration_tests/test_developer_flow_mcp_integration.py",
      "status": "FAIL",
      "duration": 0.053218,
      "start_time": "2025-06-17T06:01:55.271500",
      "end_time": "2025-06-17T06:01:55.324718",
      "stdout": "",
      "stderr": "Traceback (most recent call last):\n  File \"<frozen runpy>\", line 198, in _run_module_as_main\n  File \"<frozen runpy>\", line 88, in _run_code\n  File \"/usr/lib/python3.11/unittest/__main__.py\", line 18, in <module>\n    main(module=None)\n  File \"/usr/lib/python3.11/unittest/main.py\", line 101, in __init__\n    self.parseArgs(argv)\n  File \"/usr/lib/python3.11/unittest/main.py\", line 150, in parseArgs\n    self.createTests()\n  File \"/usr/lib/python3.11/unittest/main.py\", line 161, in createTests\n    self.test = self.testLoader.loadTestsFromNames(self.testNames,\n                ^^^^^^^^^^^^^^^^^^^^^^^^^^^^^^^^^^^^^^^^^^^^^^^^^^\n  File \"/usr/lib/python3.11/unittest/loader.py\", line 220, in loadTestsFromNames\n    suites = [self.loadTestsFromName(name, module) for name in names]\n             ^^^^^^^^^^^^^^^^^^^^^^^^^^^^^^^^^^^^^^^^^^^^^^^^^^^^^^^^\n  File \"/usr/lib/python3.11/unittest/loader.py\", line 220, in <listcomp>\n    suites = [self.loadTestsFromName(name, module) for name in names]\n              ^^^^^^^^^^^^^^^^^^^^^^^^^^^^^^^^^^^^\n  File \"/usr/lib/python3.11/unittest/loader.py\", line 154, in loadTestsFromName\n    module = __import__(module_name)\n             ^^^^^^^^^^^^^^^^^^^^^^^\n  File \"/opt/powerautomation/mcp/workflow/developer_flow_mcp/integration_tests/__init__.py\", line 1\n    \"\"\"测试模块初始化文件\"\"\"\\n\n                                      ^\nSyntaxError: unexpected character after line continuation character\n",
      "return_code": 1
    },
    {
      "module_name": "operations_workflow_mcp",
      "test_type": "unit",
      "test_file": "test_operations_workflow_mcp.py",
      "test_path": "mcp/workflow/operations_workflow_mcp/unit_tests/test_operations_workflow_mcp.py",
      "status": "FAIL",
      "duration": 0.04781,
      "start_time": "2025-06-17T06:01:55.324853",
      "end_time": "2025-06-17T06:01:55.372663",
      "stdout": "",
      "stderr": "Traceback (most recent call last):\n  File \"<frozen runpy>\", line 198, in _run_module_as_main\n  File \"<frozen runpy>\", line 88, in _run_code\n  File \"/usr/lib/python3.11/unittest/__main__.py\", line 18, in <module>\n    main(module=None)\n  File \"/usr/lib/python3.11/unittest/main.py\", line 101, in __init__\n    self.parseArgs(argv)\n  File \"/usr/lib/python3.11/unittest/main.py\", line 150, in parseArgs\n    self.createTests()\n  File \"/usr/lib/python3.11/unittest/main.py\", line 161, in createTests\n    self.test = self.testLoader.loadTestsFromNames(self.testNames,\n                ^^^^^^^^^^^^^^^^^^^^^^^^^^^^^^^^^^^^^^^^^^^^^^^^^^\n  File \"/usr/lib/python3.11/unittest/loader.py\", line 220, in loadTestsFromNames\n    suites = [self.loadTestsFromName(name, module) for name in names]\n             ^^^^^^^^^^^^^^^^^^^^^^^^^^^^^^^^^^^^^^^^^^^^^^^^^^^^^^^^\n  File \"/usr/lib/python3.11/unittest/loader.py\", line 220, in <listcomp>\n    suites = [self.loadTestsFromName(name, module) for name in names]\n              ^^^^^^^^^^^^^^^^^^^^^^^^^^^^^^^^^^^^\n  File \"/usr/lib/python3.11/unittest/loader.py\", line 154, in loadTestsFromName\n    module = __import__(module_name)\n             ^^^^^^^^^^^^^^^^^^^^^^^\n  File \"/opt/powerautomation/mcp/workflow/operations_workflow_mcp/unit_tests/__init__.py\", line 1\n    \"\"\"测试模块初始化文件\"\"\"\\n\n                                      ^\nSyntaxError: unexpected character after line continuation character\n",
      "return_code": 1
    },
    {
      "module_name": "operations_workflow_mcp",
      "test_type": "integration",
      "test_file": "test_operations_workflow_mcp_integration.py",
      "test_path": "mcp/workflow/operations_workflow_mcp/integration_tests/test_operations_workflow_mcp_integration.py",
      "status": "FAIL",
      "duration": 0.053526,
      "start_time": "2025-06-17T06:01:55.372791",
      "end_time": "2025-06-17T06:01:55.426317",
      "stdout": "",
      "stderr": "Traceback (most recent call last):\n  File \"<frozen runpy>\", line 198, in _run_module_as_main\n  File \"<frozen runpy>\", line 88, in _run_code\n  File \"/usr/lib/python3.11/unittest/__main__.py\", line 18, in <module>\n    main(module=None)\n  File \"/usr/lib/python3.11/unittest/main.py\", line 101, in __init__\n    self.parseArgs(argv)\n  File \"/usr/lib/python3.11/unittest/main.py\", line 150, in parseArgs\n    self.createTests()\n  File \"/usr/lib/python3.11/unittest/main.py\", line 161, in createTests\n    self.test = self.testLoader.loadTestsFromNames(self.testNames,\n                ^^^^^^^^^^^^^^^^^^^^^^^^^^^^^^^^^^^^^^^^^^^^^^^^^^\n  File \"/usr/lib/python3.11/unittest/loader.py\", line 220, in loadTestsFromNames\n    suites = [self.loadTestsFromName(name, module) for name in names]\n             ^^^^^^^^^^^^^^^^^^^^^^^^^^^^^^^^^^^^^^^^^^^^^^^^^^^^^^^^\n  File \"/usr/lib/python3.11/unittest/loader.py\", line 220, in <listcomp>\n    suites = [self.loadTestsFromName(name, module) for name in names]\n              ^^^^^^^^^^^^^^^^^^^^^^^^^^^^^^^^^^^^\n  File \"/usr/lib/python3.11/unittest/loader.py\", line 154, in loadTestsFromName\n    module = __import__(module_name)\n             ^^^^^^^^^^^^^^^^^^^^^^^\n  File \"/opt/powerautomation/mcp/workflow/operations_workflow_mcp/integration_tests/__init__.py\", line 1\n    \"\"\"测试模块初始化文件\"\"\"\\n\n                                      ^\nSyntaxError: unexpected character after line continuation character\n",
      "return_code": 1
    },
    {
      "module_name": "release_manager_mcp",
      "test_type": "unit",
      "test_file": "test_release_manager_mcp.py",
      "test_path": "mcp/workflow/release_manager_mcp/unit_tests/test_release_manager_mcp.py",
      "status": "FAIL",
      "duration": 0.052293,
      "start_time": "2025-06-17T06:01:55.426434",
      "end_time": "2025-06-17T06:01:55.478727",
      "stdout": "",
      "stderr": "Traceback (most recent call last):\n  File \"<frozen runpy>\", line 198, in _run_module_as_main\n  File \"<frozen runpy>\", line 88, in _run_code\n  File \"/usr/lib/python3.11/unittest/__main__.py\", line 18, in <module>\n    main(module=None)\n  File \"/usr/lib/python3.11/unittest/main.py\", line 101, in __init__\n    self.parseArgs(argv)\n  File \"/usr/lib/python3.11/unittest/main.py\", line 150, in parseArgs\n    self.createTests()\n  File \"/usr/lib/python3.11/unittest/main.py\", line 161, in createTests\n    self.test = self.testLoader.loadTestsFromNames(self.testNames,\n                ^^^^^^^^^^^^^^^^^^^^^^^^^^^^^^^^^^^^^^^^^^^^^^^^^^\n  File \"/usr/lib/python3.11/unittest/loader.py\", line 220, in loadTestsFromNames\n    suites = [self.loadTestsFromName(name, module) for name in names]\n             ^^^^^^^^^^^^^^^^^^^^^^^^^^^^^^^^^^^^^^^^^^^^^^^^^^^^^^^^\n  File \"/usr/lib/python3.11/unittest/loader.py\", line 220, in <listcomp>\n    suites = [self.loadTestsFromName(name, module) for name in names]\n              ^^^^^^^^^^^^^^^^^^^^^^^^^^^^^^^^^^^^\n  File \"/usr/lib/python3.11/unittest/loader.py\", line 154, in loadTestsFromName\n    module = __import__(module_name)\n             ^^^^^^^^^^^^^^^^^^^^^^^\n  File \"/opt/powerautomation/mcp/workflow/release_manager_mcp/unit_tests/__init__.py\", line 1\n    \"\"\"测试模块初始化文件\"\"\"\\n\n                                      ^\nSyntaxError: unexpected character after line continuation character\n",
      "return_code": 1
    },
    {
      "module_name": "release_manager_mcp",
      "test_type": "integration",
      "test_file": "test_release_manager_mcp_integration.py",
      "test_path": "mcp/workflow/release_manager_mcp/integration_tests/test_release_manager_mcp_integration.py",
      "status": "FAIL",
      "duration": 0.050383,
      "start_time": "2025-06-17T06:01:55.478866",
      "end_time": "2025-06-17T06:01:55.529249",
      "stdout": "",
      "stderr": "Traceback (most recent call last):\n  File \"<frozen runpy>\", line 198, in _run_module_as_main\n  File \"<frozen runpy>\", line 88, in _run_code\n  File \"/usr/lib/python3.11/unittest/__main__.py\", line 18, in <module>\n    main(module=None)\n  File \"/usr/lib/python3.11/unittest/main.py\", line 101, in __init__\n    self.parseArgs(argv)\n  File \"/usr/lib/python3.11/unittest/main.py\", line 150, in parseArgs\n    self.createTests()\n  File \"/usr/lib/python3.11/unittest/main.py\", line 161, in createTests\n    self.test = self.testLoader.loadTestsFromNames(self.testNames,\n                ^^^^^^^^^^^^^^^^^^^^^^^^^^^^^^^^^^^^^^^^^^^^^^^^^^\n  File \"/usr/lib/python3.11/unittest/loader.py\", line 220, in loadTestsFromNames\n    suites = [self.loadTestsFromName(name, module) for name in names]\n             ^^^^^^^^^^^^^^^^^^^^^^^^^^^^^^^^^^^^^^^^^^^^^^^^^^^^^^^^\n  File \"/usr/lib/python3.11/unittest/loader.py\", line 220, in <listcomp>\n    suites = [self.loadTestsFromName(name, module) for name in names]\n              ^^^^^^^^^^^^^^^^^^^^^^^^^^^^^^^^^^^^\n  File \"/usr/lib/python3.11/unittest/loader.py\", line 154, in loadTestsFromName\n    module = __import__(module_name)\n             ^^^^^^^^^^^^^^^^^^^^^^^\n  File \"/opt/powerautomation/mcp/workflow/release_manager_mcp/integration_tests/__init__.py\", line 1\n    \"\"\"测试模块初始化文件\"\"\"\\n\n                                      ^\nSyntaxError: unexpected character after line continuation character\n",
      "return_code": 1
    },
    {
      "module_name": "requirements_analysis_mcp",
      "test_type": "unit",
      "test_file": "test_requirements_analysis_mcp.py",
      "test_path": "mcp/workflow/requirements_analysis_mcp/unit_tests/test_requirements_analysis_mcp.py",
      "status": "FAIL",
      "duration": 0.048728,
      "start_time": "2025-06-17T06:01:55.529436",
      "end_time": "2025-06-17T06:01:55.578164",
      "stdout": "",
      "stderr": "Traceback (most recent call last):\n  File \"<frozen runpy>\", line 198, in _run_module_as_main\n  File \"<frozen runpy>\", line 88, in _run_code\n  File \"/usr/lib/python3.11/unittest/__main__.py\", line 18, in <module>\n    main(module=None)\n  File \"/usr/lib/python3.11/unittest/main.py\", line 101, in __init__\n    self.parseArgs(argv)\n  File \"/usr/lib/python3.11/unittest/main.py\", line 150, in parseArgs\n    self.createTests()\n  File \"/usr/lib/python3.11/unittest/main.py\", line 161, in createTests\n    self.test = self.testLoader.loadTestsFromNames(self.testNames,\n                ^^^^^^^^^^^^^^^^^^^^^^^^^^^^^^^^^^^^^^^^^^^^^^^^^^\n  File \"/usr/lib/python3.11/unittest/loader.py\", line 220, in loadTestsFromNames\n    suites = [self.loadTestsFromName(name, module) for name in names]\n             ^^^^^^^^^^^^^^^^^^^^^^^^^^^^^^^^^^^^^^^^^^^^^^^^^^^^^^^^\n  File \"/usr/lib/python3.11/unittest/loader.py\", line 220, in <listcomp>\n    suites = [self.loadTestsFromName(name, module) for name in names]\n              ^^^^^^^^^^^^^^^^^^^^^^^^^^^^^^^^^^^^\n  File \"/usr/lib/python3.11/unittest/loader.py\", line 154, in loadTestsFromName\n    module = __import__(module_name)\n             ^^^^^^^^^^^^^^^^^^^^^^^\n  File \"/opt/powerautomation/mcp/workflow/requirements_analysis_mcp/unit_tests/__init__.py\", line 1\n    \"\"\"测试模块初始化文件\"\"\"\\n\n                                      ^\nSyntaxError: unexpected character after line continuation character\n",
      "return_code": 1
    },
    {
      "module_name": "requirements_analysis_mcp",
      "test_type": "integration",
      "test_file": "test_requirements_analysis_mcp_integration.py",
      "test_path": "mcp/workflow/requirements_analysis_mcp/integration_tests/test_requirements_analysis_mcp_integration.py",
      "status": "FAIL",
      "duration": 0.048191,
      "start_time": "2025-06-17T06:01:55.578340",
      "end_time": "2025-06-17T06:01:55.626531",
      "stdout": "",
      "stderr": "Traceback (most recent call last):\n  File \"<frozen runpy>\", line 198, in _run_module_as_main\n  File \"<frozen runpy>\", line 88, in _run_code\n  File \"/usr/lib/python3.11/unittest/__main__.py\", line 18, in <module>\n    main(module=None)\n  File \"/usr/lib/python3.11/unittest/main.py\", line 101, in __init__\n    self.parseArgs(argv)\n  File \"/usr/lib/python3.11/unittest/main.py\", line 150, in parseArgs\n    self.createTests()\n  File \"/usr/lib/python3.11/unittest/main.py\", line 161, in createTests\n    self.test = self.testLoader.loadTestsFromNames(self.testNames,\n                ^^^^^^^^^^^^^^^^^^^^^^^^^^^^^^^^^^^^^^^^^^^^^^^^^^\n  File \"/usr/lib/python3.11/unittest/loader.py\", line 220, in loadTestsFromNames\n    suites = [self.loadTestsFromName(name, module) for name in names]\n             ^^^^^^^^^^^^^^^^^^^^^^^^^^^^^^^^^^^^^^^^^^^^^^^^^^^^^^^^\n  File \"/usr/lib/python3.11/unittest/loader.py\", line 220, in <listcomp>\n    suites = [self.loadTestsFromName(name, module) for name in names]\n              ^^^^^^^^^^^^^^^^^^^^^^^^^^^^^^^^^^^^\n  File \"/usr/lib/python3.11/unittest/loader.py\", line 154, in loadTestsFromName\n    module = __import__(module_name)\n             ^^^^^^^^^^^^^^^^^^^^^^^\n  File \"/opt/powerautomation/mcp/workflow/requirements_analysis_mcp/integration_tests/__init__.py\", line 1\n    \"\"\"测试模块初始化文件\"\"\"\\n\n                                      ^\nSyntaxError: unexpected character after line continuation character\n",
      "return_code": 1
    }
  ],
  "failed_tests_summary": [
    {
      "module": "cloud_search_mcp",
      "test_type": "unit",
      "test_file": "test_cloud_search_mcp.py",
      "status": "FAIL",
      "error": "Traceback (most recent call last):\n  File \"<frozen runpy>\", line 198, in _run_module_as_main\n  File \"<frozen runpy>\", line 88, in _run_code\n  File \"/usr/lib/python3.11/unittest/__main__.py\", line 18, in <module>\n    main(module=None)\n  File \"/usr/lib/python3.11/unittest/main.py\", line 101, in __init__\n    self.parseArgs(argv)\n  File \"/usr/lib/python3.11/unittest/main.py\", line 150, in parseArgs\n    self.createTests()\n  File \"/usr/lib/python3.11/unittest/main.py\", line 161, in createTests\n    sel"
    },
    {
      "module": "cloud_search_mcp",
      "test_type": "integration",
      "test_file": "test_cloud_search_mcp_integration.py",
      "status": "FAIL",
      "error": "Traceback (most recent call last):\n  File \"<frozen runpy>\", line 198, in _run_module_as_main\n  File \"<frozen runpy>\", line 88, in _run_code\n  File \"/usr/lib/python3.11/unittest/__main__.py\", line 18, in <module>\n    main(module=None)\n  File \"/usr/lib/python3.11/unittest/main.py\", line 101, in __init__\n    self.parseArgs(argv)\n  File \"/usr/lib/python3.11/unittest/main.py\", line 150, in parseArgs\n    self.createTests()\n  File \"/usr/lib/python3.11/unittest/main.py\", line 161, in createTests\n    sel"
    },
    {
      "module": "development_intervention_mcp",
      "test_type": "unit",
      "test_file": "test_development_intervention_mcp.py",
      "status": "FAIL",
      "error": "Traceback (most recent call last):\n  File \"<frozen runpy>\", line 198, in _run_module_as_main\n  File \"<frozen runpy>\", line 88, in _run_code\n  File \"/usr/lib/python3.11/unittest/__main__.py\", line 18, in <module>\n    main(module=None)\n  File \"/usr/lib/python3.11/unittest/main.py\", line 101, in __init__\n    self.parseArgs(argv)\n  File \"/usr/lib/python3.11/unittest/main.py\", line 150, in parseArgs\n    self.createTests()\n  File \"/usr/lib/python3.11/unittest/main.py\", line 161, in createTests\n    sel"
    },
    {
      "module": "development_intervention_mcp",
      "test_type": "integration",
      "test_file": "test_development_intervention_mcp_integration.py",
      "status": "FAIL",
      "error": "Traceback (most recent call last):\n  File \"<frozen runpy>\", line 198, in _run_module_as_main\n  File \"<frozen runpy>\", line 88, in _run_code\n  File \"/usr/lib/python3.11/unittest/__main__.py\", line 18, in <module>\n    main(module=None)\n  File \"/usr/lib/python3.11/unittest/main.py\", line 101, in __init__\n    self.parseArgs(argv)\n  File \"/usr/lib/python3.11/unittest/main.py\", line 150, in parseArgs\n    self.createTests()\n  File \"/usr/lib/python3.11/unittest/main.py\", line 161, in createTests\n    sel"
    },
    {
      "module": "directory_structure_mcp",
      "test_type": "unit",
      "test_file": "test_directory_structure_mcp.py",
      "status": "FAIL",
      "error": "Traceback (most recent call last):\n  File \"<frozen runpy>\", line 198, in _run_module_as_main\n  File \"<frozen runpy>\", line 88, in _run_code\n  File \"/usr/lib/python3.11/unittest/__main__.py\", line 18, in <module>\n    main(module=None)\n  File \"/usr/lib/python3.11/unittest/main.py\", line 101, in __init__\n    self.parseArgs(argv)\n  File \"/usr/lib/python3.11/unittest/main.py\", line 150, in parseArgs\n    self.createTests()\n  File \"/usr/lib/python3.11/unittest/main.py\", line 161, in createTests\n    sel"
    },
    {
      "module": "directory_structure_mcp",
      "test_type": "integration",
      "test_file": "test_directory_structure_mcp_integration.py",
      "status": "FAIL",
      "error": "Traceback (most recent call last):\n  File \"<frozen runpy>\", line 198, in _run_module_as_main\n  File \"<frozen runpy>\", line 88, in _run_code\n  File \"/usr/lib/python3.11/unittest/__main__.py\", line 18, in <module>\n    main(module=None)\n  File \"/usr/lib/python3.11/unittest/main.py\", line 101, in __init__\n    self.parseArgs(argv)\n  File \"/usr/lib/python3.11/unittest/main.py\", line 150, in parseArgs\n    self.createTests()\n  File \"/usr/lib/python3.11/unittest/main.py\", line 161, in createTests\n    sel"
    },
    {
      "module": "enterprise_smartui_mcp",
      "test_type": "unit",
      "test_file": "test_enterprise_smartui_mcp.py",
      "status": "FAIL",
      "error": "Traceback (most recent call last):\n  File \"<frozen runpy>\", line 198, in _run_module_as_main\n  File \"<frozen runpy>\", line 88, in _run_code\n  File \"/usr/lib/python3.11/unittest/__main__.py\", line 18, in <module>\n    main(module=None)\n  File \"/usr/lib/python3.11/unittest/main.py\", line 101, in __init__\n    self.parseArgs(argv)\n  File \"/usr/lib/python3.11/unittest/main.py\", line 150, in parseArgs\n    self.createTests()\n  File \"/usr/lib/python3.11/unittest/main.py\", line 161, in createTests\n    sel"
    },
    {
      "module": "enterprise_smartui_mcp",
      "test_type": "integration",
      "test_file": "test_enterprise_smartui_mcp_integration.py",
      "status": "FAIL",
      "error": "Traceback (most recent call last):\n  File \"<frozen runpy>\", line 198, in _run_module_as_main\n  File \"<frozen runpy>\", line 88, in _run_code\n  File \"/usr/lib/python3.11/unittest/__main__.py\", line 18, in <module>\n    main(module=None)\n  File \"/usr/lib/python3.11/unittest/main.py\", line 101, in __init__\n    self.parseArgs(argv)\n  File \"/usr/lib/python3.11/unittest/main.py\", line 150, in parseArgs\n    self.createTests()\n  File \"/usr/lib/python3.11/unittest/main.py\", line 161, in createTests\n    sel"
    },
    {
      "module": "github_mcp",
      "test_type": "unit",
      "test_file": "test_github_mcp.py",
      "status": "FAIL",
      "error": "Traceback (most recent call last):\n  File \"<frozen runpy>\", line 198, in _run_module_as_main\n  File \"<frozen runpy>\", line 88, in _run_code\n  File \"/usr/lib/python3.11/unittest/__main__.py\", line 18, in <module>\n    main(module=None)\n  File \"/usr/lib/python3.11/unittest/main.py\", line 101, in __init__\n    self.parseArgs(argv)\n  File \"/usr/lib/python3.11/unittest/main.py\", line 150, in parseArgs\n    self.createTests()\n  File \"/usr/lib/python3.11/unittest/main.py\", line 161, in createTests\n    sel"
    },
    {
      "module": "github_mcp",
      "test_type": "integration",
      "test_file": "test_github_mcp_integration.py",
      "status": "FAIL",
      "error": "Traceback (most recent call last):\n  File \"<frozen runpy>\", line 198, in _run_module_as_main\n  File \"<frozen runpy>\", line 88, in _run_code\n  File \"/usr/lib/python3.11/unittest/__main__.py\", line 18, in <module>\n    main(module=None)\n  File \"/usr/lib/python3.11/unittest/main.py\", line 101, in __init__\n    self.parseArgs(argv)\n  File \"/usr/lib/python3.11/unittest/main.py\", line 150, in parseArgs\n    self.createTests()\n  File \"/usr/lib/python3.11/unittest/main.py\", line 161, in createTests\n    sel"
    },
    {
      "module": "interaction_log_manager",
      "test_type": "unit",
      "test_file": "test_interaction_log_manager.py",
      "status": "FAIL",
      "error": "Traceback (most recent call last):\n  File \"<frozen runpy>\", line 198, in _run_module_as_main\n  File \"<frozen runpy>\", line 88, in _run_code\n  File \"/usr/lib/python3.11/unittest/__main__.py\", line 18, in <module>\n    main(module=None)\n  File \"/usr/lib/python3.11/unittest/main.py\", line 101, in __init__\n    self.parseArgs(argv)\n  File \"/usr/lib/python3.11/unittest/main.py\", line 150, in parseArgs\n    self.createTests()\n  File \"/usr/lib/python3.11/unittest/main.py\", line 161, in createTests\n    sel"
    },
    {
      "module": "interaction_log_manager",
      "test_type": "integration",
      "test_file": "test_interaction_log_manager_integration.py",
      "status": "FAIL",
      "error": "Traceback (most recent call last):\n  File \"<frozen runpy>\", line 198, in _run_module_as_main\n  File \"<frozen runpy>\", line 88, in _run_code\n  File \"/usr/lib/python3.11/unittest/__main__.py\", line 18, in <module>\n    main(module=None)\n  File \"/usr/lib/python3.11/unittest/main.py\", line 101, in __init__\n    self.parseArgs(argv)\n  File \"/usr/lib/python3.11/unittest/main.py\", line 150, in parseArgs\n    self.createTests()\n  File \"/usr/lib/python3.11/unittest/main.py\", line 161, in createTests\n    sel"
    },
    {
      "module": "test_manage_mcp",
      "test_type": "unit",
      "test_file": "test_test_manage_mcp.py",
      "status": "FAIL",
      "error": "Traceback (most recent call last):\n  File \"<frozen runpy>\", line 198, in _run_module_as_main\n  File \"<frozen runpy>\", line 88, in _run_code\n  File \"/usr/lib/python3.11/unittest/__main__.py\", line 18, in <module>\n    main(module=None)\n  File \"/usr/lib/python3.11/unittest/main.py\", line 101, in __init__\n    self.parseArgs(argv)\n  File \"/usr/lib/python3.11/unittest/main.py\", line 150, in parseArgs\n    self.createTests()\n  File \"/usr/lib/python3.11/unittest/main.py\", line 161, in createTests\n    sel"
    },
    {
      "module": "test_manage_mcp",
      "test_type": "integration",
      "test_file": "test_test_manage_mcp_integration.py",
      "status": "FAIL",
      "error": "Traceback (most recent call last):\n  File \"<frozen runpy>\", line 198, in _run_module_as_main\n  File \"<frozen runpy>\", line 88, in _run_code\n  File \"/usr/lib/python3.11/unittest/__main__.py\", line 18, in <module>\n    main(module=None)\n  File \"/usr/lib/python3.11/unittest/main.py\", line 101, in __init__\n    self.parseArgs(argv)\n  File \"/usr/lib/python3.11/unittest/main.py\", line 150, in parseArgs\n    self.createTests()\n  File \"/usr/lib/python3.11/unittest/main.py\", line 161, in createTests\n    sel"
    },
    {
      "module": "kilocode_mcp",
      "test_type": "unit",
      "test_file": "test_kilocode_mcp.py",
      "status": "FAIL",
      "error": "Traceback (most recent call last):\n  File \"<frozen runpy>\", line 198, in _run_module_as_main\n  File \"<frozen runpy>\", line 88, in _run_code\n  File \"/usr/lib/python3.11/unittest/__main__.py\", line 18, in <module>\n    main(module=None)\n  File \"/usr/lib/python3.11/unittest/main.py\", line 101, in __init__\n    self.parseArgs(argv)\n  File \"/usr/lib/python3.11/unittest/main.py\", line 150, in parseArgs\n    self.createTests()\n  File \"/usr/lib/python3.11/unittest/main.py\", line 161, in createTests\n    sel"
    },
    {
      "module": "kilocode_mcp",
      "test_type": "integration",
      "test_file": "test_kilocode_mcp_integration.py",
      "status": "FAIL",
      "error": "Traceback (most recent call last):\n  File \"<frozen runpy>\", line 198, in _run_module_as_main\n  File \"<frozen runpy>\", line 88, in _run_code\n  File \"/usr/lib/python3.11/unittest/__main__.py\", line 18, in <module>\n    main(module=None)\n  File \"/usr/lib/python3.11/unittest/main.py\", line 101, in __init__\n    self.parseArgs(argv)\n  File \"/usr/lib/python3.11/unittest/main.py\", line 150, in parseArgs\n    self.createTests()\n  File \"/usr/lib/python3.11/unittest/main.py\", line 161, in createTests\n    sel"
    },
    {
      "module": "local_model_mcp",
      "test_type": "unit",
      "test_file": "test_local_model_mcp.py",
      "status": "FAIL",
      "error": "Traceback (most recent call last):\n  File \"<frozen runpy>\", line 198, in _run_module_as_main\n  File \"<frozen runpy>\", line 88, in _run_code\n  File \"/usr/lib/python3.11/unittest/__main__.py\", line 18, in <module>\n    main(module=None)\n  File \"/usr/lib/python3.11/unittest/main.py\", line 101, in __init__\n    self.parseArgs(argv)\n  File \"/usr/lib/python3.11/unittest/main.py\", line 150, in parseArgs\n    self.createTests()\n  File \"/usr/lib/python3.11/unittest/main.py\", line 161, in createTests\n    sel"
    },
    {
      "module": "local_model_mcp",
      "test_type": "integration",
      "test_file": "test_local_model_mcp_integration.py",
      "status": "FAIL",
      "error": "Traceback (most recent call last):\n  File \"<frozen runpy>\", line 198, in _run_module_as_main\n  File \"<frozen runpy>\", line 88, in _run_code\n  File \"/usr/lib/python3.11/unittest/__main__.py\", line 18, in <module>\n    main(module=None)\n  File \"/usr/lib/python3.11/unittest/main.py\", line 101, in __init__\n    self.parseArgs(argv)\n  File \"/usr/lib/python3.11/unittest/main.py\", line 150, in parseArgs\n    self.createTests()\n  File \"/usr/lib/python3.11/unittest/main.py\", line 161, in createTests\n    sel"
    },
    {
      "module": "enhanced_workflow_mcp",
      "test_type": "unit",
      "test_file": "test_enhanced_workflow_mcp.py",
      "status": "FAIL",
      "error": "Traceback (most recent call last):\n  File \"<frozen runpy>\", line 198, in _run_module_as_main\n  File \"<frozen runpy>\", line 88, in _run_code\n  File \"/usr/lib/python3.11/unittest/__main__.py\", line 18, in <module>\n    main(module=None)\n  File \"/usr/lib/python3.11/unittest/main.py\", line 101, in __init__\n    self.parseArgs(argv)\n  File \"/usr/lib/python3.11/unittest/main.py\", line 150, in parseArgs\n    self.createTests()\n  File \"/usr/lib/python3.11/unittest/main.py\", line 161, in createTests\n    sel"
    },
    {
      "module": "enhanced_workflow_mcp",
      "test_type": "integration",
      "test_file": "test_enhanced_workflow_mcp_integration.py",
      "status": "FAIL",
      "error": "Traceback (most recent call last):\n  File \"<frozen runpy>\", line 198, in _run_module_as_main\n  File \"<frozen runpy>\", line 88, in _run_code\n  File \"/usr/lib/python3.11/unittest/__main__.py\", line 18, in <module>\n    main(module=None)\n  File \"/usr/lib/python3.11/unittest/main.py\", line 101, in __init__\n    self.parseArgs(argv)\n  File \"/usr/lib/python3.11/unittest/main.py\", line 150, in parseArgs\n    self.createTests()\n  File \"/usr/lib/python3.11/unittest/main.py\", line 161, in createTests\n    sel"
    },
    {
      "module": "architecture_design_mcp",
      "test_type": "unit",
      "test_file": "test_architecture_design_mcp.py",
      "status": "FAIL",
      "error": "Traceback (most recent call last):\n  File \"<frozen runpy>\", line 198, in _run_module_as_main\n  File \"<frozen runpy>\", line 88, in _run_code\n  File \"/usr/lib/python3.11/unittest/__main__.py\", line 18, in <module>\n    main(module=None)\n  File \"/usr/lib/python3.11/unittest/main.py\", line 101, in __init__\n    self.parseArgs(argv)\n  File \"/usr/lib/python3.11/unittest/main.py\", line 150, in parseArgs\n    self.createTests()\n  File \"/usr/lib/python3.11/unittest/main.py\", line 161, in createTests\n    sel"
    },
    {
      "module": "architecture_design_mcp",
      "test_type": "integration",
      "test_file": "test_architecture_design_mcp_integration.py",
      "status": "FAIL",
      "error": "Traceback (most recent call last):\n  File \"<frozen runpy>\", line 198, in _run_module_as_main\n  File \"<frozen runpy>\", line 88, in _run_code\n  File \"/usr/lib/python3.11/unittest/__main__.py\", line 18, in <module>\n    main(module=None)\n  File \"/usr/lib/python3.11/unittest/main.py\", line 101, in __init__\n    self.parseArgs(argv)\n  File \"/usr/lib/python3.11/unittest/main.py\", line 150, in parseArgs\n    self.createTests()\n  File \"/usr/lib/python3.11/unittest/main.py\", line 161, in createTests\n    sel"
    },
    {
      "module": "coding_workflow_mcp",
      "test_type": "unit",
      "test_file": "test_coding_workflow_mcp.py",
      "status": "FAIL",
      "error": "Traceback (most recent call last):\n  File \"<frozen runpy>\", line 198, in _run_module_as_main\n  File \"<frozen runpy>\", line 88, in _run_code\n  File \"/usr/lib/python3.11/unittest/__main__.py\", line 18, in <module>\n    main(module=None)\n  File \"/usr/lib/python3.11/unittest/main.py\", line 101, in __init__\n    self.parseArgs(argv)\n  File \"/usr/lib/python3.11/unittest/main.py\", line 150, in parseArgs\n    self.createTests()\n  File \"/usr/lib/python3.11/unittest/main.py\", line 161, in createTests\n    sel"
    },
    {
      "module": "coding_workflow_mcp",
      "test_type": "integration",
      "test_file": "test_coding_workflow_mcp_integration.py",
      "status": "FAIL",
      "error": "Traceback (most recent call last):\n  File \"<frozen runpy>\", line 198, in _run_module_as_main\n  File \"<frozen runpy>\", line 88, in _run_code\n  File \"/usr/lib/python3.11/unittest/__main__.py\", line 18, in <module>\n    main(module=None)\n  File \"/usr/lib/python3.11/unittest/main.py\", line 101, in __init__\n    self.parseArgs(argv)\n  File \"/usr/lib/python3.11/unittest/main.py\", line 150, in parseArgs\n    self.createTests()\n  File \"/usr/lib/python3.11/unittest/main.py\", line 161, in createTests\n    sel"
    },
    {
      "module": "developer_flow_mcp",
      "test_type": "unit",
      "test_file": "test_developer_flow_mcp.py",
      "status": "FAIL",
      "error": "Traceback (most recent call last):\n  File \"<frozen runpy>\", line 198, in _run_module_as_main\n  File \"<frozen runpy>\", line 88, in _run_code\n  File \"/usr/lib/python3.11/unittest/__main__.py\", line 18, in <module>\n    main(module=None)\n  File \"/usr/lib/python3.11/unittest/main.py\", line 101, in __init__\n    self.parseArgs(argv)\n  File \"/usr/lib/python3.11/unittest/main.py\", line 150, in parseArgs\n    self.createTests()\n  File \"/usr/lib/python3.11/unittest/main.py\", line 161, in createTests\n    sel"
    },
    {
      "module": "developer_flow_mcp",
      "test_type": "integration",
      "test_file": "test_developer_flow_mcp_integration.py",
      "status": "FAIL",
      "error": "Traceback (most recent call last):\n  File \"<frozen runpy>\", line 198, in _run_module_as_main\n  File \"<frozen runpy>\", line 88, in _run_code\n  File \"/usr/lib/python3.11/unittest/__main__.py\", line 18, in <module>\n    main(module=None)\n  File \"/usr/lib/python3.11/unittest/main.py\", line 101, in __init__\n    self.parseArgs(argv)\n  File \"/usr/lib/python3.11/unittest/main.py\", line 150, in parseArgs\n    self.createTests()\n  File \"/usr/lib/python3.11/unittest/main.py\", line 161, in createTests\n    sel"
    },
    {
      "module": "operations_workflow_mcp",
      "test_type": "unit",
      "test_file": "test_operations_workflow_mcp.py",
      "status": "FAIL",
      "error": "Traceback (most recent call last):\n  File \"<frozen runpy>\", line 198, in _run_module_as_main\n  File \"<frozen runpy>\", line 88, in _run_code\n  File \"/usr/lib/python3.11/unittest/__main__.py\", line 18, in <module>\n    main(module=None)\n  File \"/usr/lib/python3.11/unittest/main.py\", line 101, in __init__\n    self.parseArgs(argv)\n  File \"/usr/lib/python3.11/unittest/main.py\", line 150, in parseArgs\n    self.createTests()\n  File \"/usr/lib/python3.11/unittest/main.py\", line 161, in createTests\n    sel"
    },
    {
      "module": "operations_workflow_mcp",
      "test_type": "integration",
      "test_file": "test_operations_workflow_mcp_integration.py",
      "status": "FAIL",
      "error": "Traceback (most recent call last):\n  File \"<frozen runpy>\", line 198, in _run_module_as_main\n  File \"<frozen runpy>\", line 88, in _run_code\n  File \"/usr/lib/python3.11/unittest/__main__.py\", line 18, in <module>\n    main(module=None)\n  File \"/usr/lib/python3.11/unittest/main.py\", line 101, in __init__\n    self.parseArgs(argv)\n  File \"/usr/lib/python3.11/unittest/main.py\", line 150, in parseArgs\n    self.createTests()\n  File \"/usr/lib/python3.11/unittest/main.py\", line 161, in createTests\n    sel"
    },
    {
      "module": "release_manager_mcp",
      "test_type": "unit",
      "test_file": "test_release_manager_mcp.py",
      "status": "FAIL",
      "error": "Traceback (most recent call last):\n  File \"<frozen runpy>\", line 198, in _run_module_as_main\n  File \"<frozen runpy>\", line 88, in _run_code\n  File \"/usr/lib/python3.11/unittest/__main__.py\", line 18, in <module>\n    main(module=None)\n  File \"/usr/lib/python3.11/unittest/main.py\", line 101, in __init__\n    self.parseArgs(argv)\n  File \"/usr/lib/python3.11/unittest/main.py\", line 150, in parseArgs\n    self.createTests()\n  File \"/usr/lib/python3.11/unittest/main.py\", line 161, in createTests\n    sel"
    },
    {
      "module": "release_manager_mcp",
      "test_type": "integration",
      "test_file": "test_release_manager_mcp_integration.py",
      "status": "FAIL",
      "error": "Traceback (most recent call last):\n  File \"<frozen runpy>\", line 198, in _run_module_as_main\n  File \"<frozen runpy>\", line 88, in _run_code\n  File \"/usr/lib/python3.11/unittest/__main__.py\", line 18, in <module>\n    main(module=None)\n  File \"/usr/lib/python3.11/unittest/main.py\", line 101, in __init__\n    self.parseArgs(argv)\n  File \"/usr/lib/python3.11/unittest/main.py\", line 150, in parseArgs\n    self.createTests()\n  File \"/usr/lib/python3.11/unittest/main.py\", line 161, in createTests\n    sel"
    },
    {
      "module": "requirements_analysis_mcp",
      "test_type": "unit",
      "test_file": "test_requirements_analysis_mcp.py",
      "status": "FAIL",
      "error": "Traceback (most recent call last):\n  File \"<frozen runpy>\", line 198, in _run_module_as_main\n  File \"<frozen runpy>\", line 88, in _run_code\n  File \"/usr/lib/python3.11/unittest/__main__.py\", line 18, in <module>\n    main(module=None)\n  File \"/usr/lib/python3.11/unittest/main.py\", line 101, in __init__\n    self.parseArgs(argv)\n  File \"/usr/lib/python3.11/unittest/main.py\", line 150, in parseArgs\n    self.createTests()\n  File \"/usr/lib/python3.11/unittest/main.py\", line 161, in createTests\n    sel"
    },
    {
      "module": "requirements_analysis_mcp",
      "test_type": "integration",
      "test_file": "test_requirements_analysis_mcp_integration.py",
      "status": "FAIL",
      "error": "Traceback (most recent call last):\n  File \"<frozen runpy>\", line 198, in _run_module_as_main\n  File \"<frozen runpy>\", line 88, in _run_code\n  File \"/usr/lib/python3.11/unittest/__main__.py\", line 18, in <module>\n    main(module=None)\n  File \"/usr/lib/python3.11/unittest/main.py\", line 101, in __init__\n    self.parseArgs(argv)\n  File \"/usr/lib/python3.11/unittest/main.py\", line 150, in parseArgs\n    self.createTests()\n  File \"/usr/lib/python3.11/unittest/main.py\", line 161, in createTests\n    sel"
    }
  ]
}